Workbook

Sheet Dashboard
B1: ASG CARD
B2: Financial Model v5 (Audited)
A4: WHAT IS ASG CARD?
B5: ASG Card issues instant virtual Visa cards for AI agents via API.
B6: Payments settled in USDC on the Stellar blockchain using x402 protocol.
B7: "Payment IS Authentication" — no API keys, no KYC, no registration needed.
B8: Agent sends USDC → gets a virtual card → makes purchases autonomously.
B10: Revenue: per-transaction fees (topUpFee + serviceFee) + $29/mo Pro subscription.
B11: Card issuer: 4payments ($3/card + 3% deposit). Grant: SCF #42 (Stellar).
B12: Stage: Pre-launch pilot. Target: production on Stellar by May 2026.
A14: KEY METRICS
B15: Net Margin /client | C15: Break-Even Clients | D15: LTV/CAC | E15: Mo12 Revenue | F15: Mo12 Paying | G15: Free Card Budget Left
B16: =Assumptions!C32 | C16: ='P&L'!B31 | D16: ='Unit Economics'!C26 | E16: ='P&L'!M9 | F16: ='User Growth'!M22 | G16: ='XLM Rewards'!M22
A18: MODEL TABS
B19: → Assumptions | C19: Editable inputs: 4payments costs, pricing, Pro subscription, growth
B20: → Unit Economics | C20: Real margin per transaction after 4payments fees
B21: → User Growth | C21: Signup→Free→Paid funnel, declining churn, ramped Pro
B22: → P&L | C22: Revenue (PPU + Sub), COGS, fixed costs, XLM rewards, break-even
B23: → XLM Rewards ★ | C23: Free cards, XLM bonuses, strategy steps, SCF grant ROI
B24: → Sensitivity | C24: What-if tables: break-even × margin, LTV/CAC × churn
B25: → KPI Dashboard | C25: Weekly tracking: signups, MRR, churn, XLM metrics
B27: 💡 Blue cells = editable. All formulas auto-propagate. XLM costs feed into P&L.

Sheet Assumptions
A1: ASG CARD — MODEL ASSUMPTIONS (v5 — Audited)
A2: Blue cells = editable. Audit fixes: correct ARPU, declining churn, ramped Pro.
A4: 4PAYMENTS REAL COST STRUCTURE
A5: Parameter | B5: Current | C5: At Volume | E5: Notes
A6: Setup Fee (one-time) | B6: 4500 | C6: — | E6: One-time integration fee
A7: Card Issuance ($/card) | B7: 3 | C7: 2.5 | E7: Volume discount at 100+ cards/mo
A8: Deposit Fee (%) | B8: 3 | C8: 2 | E8: Volume discount negotiable
A9: Monthly Platform Fee ($) | B9: 75 | C9: — | E9: Fixed monthly
A11: YOUR REVENUE PER TRANSACTION (topUpFee + serviceFee)
A12: Parameter | B12: Pessimistic | C12: Realistic | D12: Optimistic | E12: Notes
A13: Avg topUpFee earned / create ($) | B13: 2.2 | C13: 3 | D13: 6 | E13: From pricing.ts, you keep this
A14: Avg serviceFee / create ($) | B14: 2 | C14: 2.5 | D14: 5 | E14: Your service margin
A15: Avg topUpFee earned / fund ($) | B15: 2.2 | C15: 3 | D15: 6 | E15: Funding topUp fee
A16: Avg serviceFee / fund ($) | B16: 2 | C16: 2 | D16: 3 | E16: Funding service fee
A17: Card Creates / client / mo | B17: 2 | C17: 4 | D17: 8 | E17: Monthly issuance volume
A18: Card Funds / client / mo | B18: 1 | C18: 2 | D18: 4 | E18: Monthly funding volume
A19: Avg loadAmount for creates ($) | B19: 25 | C19: 50 | D19: 100 | E19: For 4p deposit % calc
A20: Avg fundAmount for funds ($) | B20: 25 | C20: 50 | D20: 100 | E20: For 4p deposit % calc
A22: PRO SUBSCRIPTION ($29/mo) — RAMPED CONVERSION
A23: Parameter | B23: Pessimistic | C23: Realistic | D23: Optimistic | E23: Notes
A24: Pro Price ($/mo) | B24: 29 | C24: 29 | D24: 29 | E24: Monthly subscription
A25: Mo 1 Pro Conversion % | B25: 0 | C25: 0 | D25: 5 | E25: Start at 0% — no track record yet
A26: Mo 6 Pro Conversion % | B26: 5 | C26: 10 | D26: 20 | E26: After proving value
A27: Mo 12 Pro Conversion % | B27: 10 | C27: 20 | D27: 35 | E27: Mature conversion rate
A29: CALCULATED ARPU (topUpFee + serviceFee - 4p COGS)
A30: Gross Revenue / client / mo | B30: =(B13+B14)*B17+(B15+B16)*B18 | C30: =(C13+C14)*C17+(C15+C16)*C18 | D30: =(D13+D14)*D17+(D15+D16)*D18 | E30: (topUp+svc)×creates + (topUp+svc)×funds
A31: 4p COGS / client / mo | B31: =B7*B17+B8/100*B19*B17+B8/100*B20*B18 | C31: =B7*C17+B8/100*C19*C17+B8/100*C20*C18 | D31: =B7*D17+B8/100*D19*D17+B8/100*D20*D18 | E31: $3×creates + 3%×load×creates + 3%×fund×funds
A32: ★ NET MARGIN / client / mo (PPU) | B32: =B30-B31 | C32: =C30-C31 | D32: =D30-D31 | E32: Revenue minus 4payments variable costs
A34: GROWTH & CONVERSION (DECLINING CHURN)
A35: Parameter | B35: Pessimistic | C35: Realistic | D35: Optimistic | E35: Notes
A36: Month 1 Signups | B36: 10 | C36: 20 | D36: 30 | E36: Free tier = low friction
A37: MoM Signup Growth % | B37: 15 | C37: 25 | D37: 35 | E37: Monthly growth rate
A38: Signup → Free User % | B38: 25 | C38: 40 | D38: 60 | E38: Free tier conversion (no cost)
A39: Free → Paying % | B39: 15 | C39: 25 | D39: 40 | E39: Upgrade to paid over lifetime
A40: Mo 1-3 Churn % | B40: 15 | C40: 12 | D40: 8 | E40: Early stage — high churn
A41: Mo 4-6 Churn % | B41: 10 | C41: 8 | D41: 5 | E41: Stabilizing
A42: Mo 7-12 Churn % | B42: 8 | C42: 5 | D42: 3 | E42: Product-market fit
A44: MONTHLY FIXED COSTS ($)
A45: Category | B45: Pessimistic | C45: Realistic | D45: Optimistic | E45: Notes
A46: Hosting (Vercel+Supabase+Stellar) | B46: 100 | C46: 150 | D46: 200 | E46: Scales with usage
...

Sheet Unit Economics
A1: UNIT ECONOMICS (AUDITED)
A3: REAL MARGIN PER CREATE TRANSACTION
A4: Tier | B4: You Charge | C4: 4p Cost | D4: YOUR Net | E4: Margin % | F4: Notes
A5: Create $10 | B5: 4.2 | C5: 3.3 | D5: 0.9 | E5: 21% | F5: ⚠️ Thin
A6: Create $25 | B6: 4.5 | C6: 3.75 | D6: 0.75 | E6: 17% | F6: ⚠️ Thin
A7: Create $50 | B7: 5 | C7: 4.5 | D7: 0.5 | E7: 10% | F7: ⚠️ Thin
A8: Create $100 | B8: 7 | C8: 6 | D8: 1 | E8: 14% | F8: ✅ OK
A9: Create $200 | B9: 11 | C9: 9 | D9: 2 | E9: 18% | F9: ✅ Good
A10: Create $500 | B10: 19 | C10: 18 | D10: 1 | E10: 5% | F10: ✅ OK
A12: REAL MARGIN PER FUND TRANSACTION
A13: Tier | B13: You Charge | C13: 4p Cost | D13: YOUR Net | E13: Margin % | F13: Notes
A14: Fund $10 | B14: 4.2 | C14: 0.3 | D14: 3.9 | E14: 93% | F14: ✅ Good
A15: Fund $25 | B15: 4.5 | C15: 0.75 | D15: 3.75 | E15: 83% | F15: ✅ Good
A16: Fund $50 | B16: 5 | C16: 1.5 | D16: 3.5 | E16: 70% | F16: ✅ Good
A17: Fund $100 | B17: 7 | C17: 3 | D17: 4 | E17: 57% | F17: ✅ Good
A18: Fund $200 | B18: 11 | C18: 6 | D18: 5 | E18: 45% | F18: ✅ Good
A19: Fund $500 | B19: 19 | C19: 15 | D19: 4 | E19: 21% | F19: ✅ Good
A21: KEY RATIOS (linked to Assumptions)
A22: Metric | B22: Pessimistic | C22: Realistic | D22: Optimistic | F22: Formula
A23: Net Margin/client ($/mo) | B23: =Assumptions!B32 | C23: =Assumptions!C32 | D23: =Assumptions!D32 | F23: After 4p COGS
A24: CAC ($) | B24: =Assumptions!B60 | C24: =Assumptions!C60 | D24: =Assumptions!D60 | F24: Blended
A25: LTV ($) | B25: =B23*Assumptions!B61 | C25: =C23*Assumptions!C61 | D25: =D23*Assumptions!D61 | F25: Margin×Lifetime
A26: LTV/CAC | B26: =B25/B24 | C26: =C25/C24 | D26: =D25/D24 | F26: Target: >3x
A27: Payback (mo) | B27: =B24/B23 | C27: =C24/C23 | D27: =D24/D23 | F27: CAC/Margin

Sheet User Growth
A1: USER GROWTH — REALISTIC (Declining Churn)
B2: Mo 1 | C2: Mo 2 | D2: Mo 3 | E2: Mo 4 | F2: Mo 5 | G2: Mo 6 | H2: Mo 7 | I2: Mo 8 | J2: Mo 9 | K2: Mo 10 | L2: Mo 11 | M2: Mo 12
A3: New Signups | B3: =Assumptions!C36 | C3: =ROUND(B3*(1+Assumptions!C37/100),0) | D3: =ROUND(C3*(1+Assumptions!C37/100),0) | E3: =ROUND(D3*(1+Assumptions!C37/100),0) | F3: =ROUND(E3*(1+Assumptions!C37/100),0) | G3: =ROUND(F3*(1+Assumptions!C37/100),0) | H3: =ROUND(G3*(1+Assumptions!C37/100),0) | I3: =ROUND(H3*(1+Assumptions!C37/100),0) | J3: =ROUND(I3*(1+Assumptions!C37/100),0) | K3: =ROUND(J3*(1+Assumptions!C37/100),0) | L3: =ROUND(K3*(1+Assumptions!C37/100),0) | M3: =ROUND(L3*(1+Assumptions!C37/100),0)
A4: New Free Users | B4: =ROUND(B3*Assumptions!C38/100,0) | C4: =ROUND(C3*Assumptions!C38/100,0) | D4: =ROUND(D3*Assumptions!C38/100,0) | E4: =ROUND(E3*Assumptions!C38/100,0) | F4: =ROUND(F3*Assumptions!C38/100,0) | G4: =ROUND(G3*Assumptions!C38/100,0) | H4: =ROUND(H3*Assumptions!C38/100,0) | I4: =ROUND(I3*Assumptions!C38/100,0) | J4: =ROUND(J3*Assumptions!C38/100,0) | K4: =ROUND(K3*Assumptions!C38/100,0) | L4: =ROUND(L3*Assumptions!C38/100,0) | M4: =ROUND(M3*Assumptions!C38/100,0)
A5: New Paying (free→paid) | B5: =ROUND(B4*Assumptions!C39/100,0) | C5: =ROUND(C4*Assumptions!C39/100,0) | D5: =ROUND(D4*Assumptions!C39/100,0) | E5: =ROUND(E4*Assumptions!C39/100,0) | F5: =ROUND(F4*Assumptions!C39/100,0) | G5: =ROUND(G4*Assumptions!C39/100,0) | H5: =ROUND(H4*Assumptions!C39/100,0) | I5: =ROUND(I4*Assumptions!C39/100,0) | J5: =ROUND(J4*Assumptions!C39/100,0) | K5: =ROUND(K4*Assumptions!C39/100,0) | L5: =ROUND(L4*Assumptions!C39/100,0) | M5: =ROUND(M4*Assumptions!C39/100,0)
A6: Churned (declining) | B6: 0 | C6: =ROUND(B7*Assumptions!C40/100,0) | D6: =ROUND(C7*Assumptions!C40/100,0) | E6: =ROUND(D7*Assumptions!C41/100,0) | F6: =ROUND(E7*Assumptions!C41/100,0) | G6: =ROUND(F7*Assumptions!C41/100,0) | H6: =ROUND(G7*Assumptions!C42/100,0) | I6: =ROUND(H7*Assumptions!C42/100,0) | J6: =ROUND(I7*Assumptions!C42/100,0) | K6: =ROUND(J7*Assumptions!C42/100,0) | L6: =ROUND(K7*Assumptions!C42/100,0) | M6: =ROUND(L7*Assumptions!C42/100,0)
A7: TOTAL ACTIVE PAYING | B7: =B5 | C7: =B7+C5-C6 | D7: =C7+D5-D6 | E7: =D7+E5-E6 | F7: =E7+F5-F6 | G7: =F7+G5-G6 | H7: =G7+H5-H6 | I7: =H7+I5-I6 | J7: =I7+J5-J6 | ... M7: =L7+M5-M6
A8: ↳ Pro Subscribers | B8: =ROUND(B7*Assumptions!C25/100,0) | C8: =ROUND(C7*(Assumptions!C25+(Assumptions!C26-Assumptions!C25)*(2-1)/5)/100,0) | D8: =ROUND(D7*(Assumptions!C25+(Assumptions!C26-Assumptions!C25)*(3-1)/5)/100,0) | E8: =ROUND(E7*(Assumptions!C25+(Assumptions!C26-Assumptions!C25)*(4-1)/5)/100,0) | F8: =ROUND(F7*(Assumptions!C25+(Assumptions!C26-Assumptions!C25)*(5-1)/5)/100,0) | G8: =ROUND(G7*(Assumptions!C25+(Assumptions!C26-Assumptions!C25)*(6-1)/5)/100,0) | H8: =ROUND(H7*(Assumptions!C26+(Assumptions!C27-Assumptions!C26)*(7-6)/6)/100,0) | I8: =ROUND(I7*(Assumptions!C26+(Assumptions!C27-Assumptions!C26)*(8-6)/6)/100,0) | J8: =ROUND(J7*(Assumptions!C26+(Assumptions!C27-Assumptions!C26)*(9-6)/6)/100,0) | K8: =ROUND(K7*(Assumptions!C26+(Assumptions!C27-Assumptions!C26)*(10-6)/6)/100,0) | L8: =ROUND(L7*(Assumptions!C26+(Assumptions!C27-Assumptions!C26)*(11-6)/6)/100,0) | M8: =ROUND(M7*(Assumptions!C26+(Assumptions!C27-Assumptions!C26)*(12-6)/6)/100,0)
A9: Cumulative Signups | B9: =B3 | C9: =B9+C3 | D9: =C9+D3 | E9: =D9+E3 | F9: =E9+F3 | G9: =F9+G3 | H9: =G9+H3 | I9: =H9+I3 | J9: =I9+J3 | ... M9: =L9+M3
A22: USER GROWTH — PESSIMISTIC (Declining Churn)
B23: Mo 1 | C23: Mo 2 | D23: Mo 3 | E23: Mo 4 | F23: Mo 5 | G23: Mo 6 | H23: Mo 7 | I23: Mo 8 | J23: Mo 9 | K23: Mo 10 | L23: Mo 11 | M23: Mo 12
A24: New Signups | B24: =Assumptions!B36 | C24: =ROUND(B24*(1+Assumptions!B37/100),0) | D24: =ROUND(C24*(1+Assumptions!B37/100),0) | E24: =ROUND(D24*(1+Assumptions!B37/100),0) | F24: =ROUND(E24*(1+Assumptions!B37/100),0) | G24: =ROUND(F24*(1+Assumptions!B37/100),0) | H24: =ROUND(G24*(1+Assumptions!B37/100),0) | I24: =ROUND(H24*(1+Assumptions!B37/100),0) | J24: =ROUND(I24*(1+Assumptions!B37/100),0) | K24: =ROUND(J24*(1+Assumptions!B37/100),0) | L24: =ROUND(K24*(1+Assumptions!B37/100),0) | M24: =ROUND(L24*(1+Assumptions!B37/100),0)
A25: New Free Users | B25: =ROUND(B24*Assumptions!B38/100,0) | C25: =ROUND(C24*Assumptions!B38/100,0) | D25: =ROUND(D24*Assumptions!B38/100,0) | E25: =ROUND(E24*Assumptions!B38/100,0) | F25: =ROUND(F24*Assumptions!B38/100,0) | G25: =ROUND(G24*Assumptions!B38/100,0) | H25: =ROUND(H24*Assumptions!B38/100,0) | I25: =ROUND(I24*Assumptions!B38/100,0) | J25: =ROUND(J24*Assumptions!B38/100,0) | K25: =ROUND(K24*Assumptions!B38/100,0) | L25: =ROUND(L24*Assumptions!B38/100,0) | M25: =ROUND(M24*Assumptions!B38/100,0)
A26: New Paying (free→paid) | B26: =ROUND(B25*Assumptions!B39/100,0) | C26: =ROUND(C25*Assumptions!B39/100,0) | D26: =ROUND(D25*Assumptions!B39/100,0) | E26: =ROUND(E25*Assumptions!B39/100,0) | F26: =ROUND(F25*Assumptions!B39/100,0) | G26: =ROUND(G25*Assumptions!B39/100,0) | H26: =ROUND(H25*Assumptions!B39/100,0) | I26: =ROUND(I25*Assumptions!B39/100,0) | J26: =ROUND(J25*Assumptions!B39/100,0) | K26: =ROUND(K25*Assumptions!B39/100,0) | L26: =ROUND(L25*Assumptions!B39/100,0) | M26: =ROUND(M25*Assumptions!B39/100,0)
A27: Churned (declining) | B27: 0 | C27: =ROUND(B28*Assumptions!B40/100,0) | D27: =ROUND(C28*Assumptions!B40/100,0) | E27: =ROUND(D28*Assumptions!B41/100,0) | F27: =ROUND(E28*Assumptions!B41/100,0) | G27: =ROUND(F28*Assumptions!B41/100,0) | H27: =ROUND(G28*Assumptions!B42/100,0) | I27: =ROUND(H28*Assumptions!B42/100,0) | J27: =ROUND(I28*Assumptions!B42/100,0) | K27: =ROUND(J28*Assumptions!B42/100,0) | L27: =ROUND(K28*Assumptions!B42/100,0) | M27: =ROUND(L28*Assumptions!B42/100,0)
A28: TOTAL ACTIVE PAYING | B28: =B26 | C28: =B28+C26-C27 | D28: =C28+D26-D27 | E28: =D28+E26-E27 | F28: =E28+F26-F27 | G28: =F28+G26-G27 | H28: =G28+H26-H27 | I28: =H28+I26-I27 | J28: =I28+J26-J27 | ... M28: =L28+M26-M27
A29: ↳ Pro Subscribers | B29: =ROUND(B28*Assumptions!B25/100,0) | C29: =ROUND(C28*(Assumptions!B25+(Assumptions!B26-Assumptions!B25)*(2-1)/5)/100,0) | D29: =ROUND(D28*(Assumptions!B25+(Assumptions!B26-Assumptions!B25)*(3-1)/5)/100,0) | E29: =ROUND(E28*(Assumptions!B25+(Assumptions!B26-Assumptions!B25)*(4-1)/5)/100,0) | F29: =ROUND(F28*(Assumptions!B25+(Assumptions!B26-Assumptions!B25)*(5-1)/5)/100,0) | G29: =ROUND(G28*(Assumptions!B25+(Assumptions!B26-Assumptions!B25)*(6-1)/5)/100,0) | H29: =ROUND(H28*(Assumptions!B26+(Assumptions!B27-Assumptions!B26)*(7-6)/6)/100,0) | I29: =ROUND(I28*(Assumptions!B26+(Assumptions!B27-Assumptions!B26)*(8-6)/6)/100,0) | J29: =ROUND(J28*(Assumptions!B26+(Assumptions!B27-Assumptions!B26)*(9-6)/6)/100,0) | K29: =ROUND(K28*(Assumptions!B26+(Assumptions!B27-Assumptions!B26)*(10-6)/6)/100,0) | L29: =ROUND(L28*(Assumptions!B26+(Assumptions!B27-Assumptions!B26)*(11-6)/6)/100,0) | M29: =ROUND(M28*(Assumptions!B26+(Assumptions!B27-Assumptions!B26)*(12-6)/6)/100,0)
A30: Cumulative Signups | B30: =B24 | C30: =B30+C24 | D30: =C30+D24 | E30: =D30+E24 | F30: =E30+F24 | G30: =F30+G24 | H30: =G30+H24 | I30: =H30+I24 | J30: =I30+J24 | ... M30: =L30+M24

Sheet P&L
A1: P&L — REALISTIC (AUDITED)
B2: Mo 1 | C2: Mo 2 | D2: Mo 3 | E2: Mo 4 | F2: Mo 5 | G2: Mo 6 | H2: Mo 7 | I2: Mo 8 | J2: Mo 9 | K2: Mo 10 | L2: Mo 11 | M2: Mo 12
A3: 4p Setup Fee (Mo 1 only) | B3: =Assumptions!B56 | C3: 0 | D3: 0 | E3: 0 | F3: 0 | G3: 0 | H3: 0 | I3: 0 | J3: 0 | K3: 0 | L3: 0 | M3: 0
A5: REVENUE
A6: Active Paying Clients | B6: ='User Growth'!B22 | C6: ='User Growth'!C22 | D6: ='User Growth'!D22 | E6: ='User Growth'!E22 | F6: ='User Growth'!F22 | G6: ='User Growth'!G22 | H6: ='User Growth'!H22 | I6: ='User Growth'!I22 | ... M6: ='User Growth'!M22
A7: PPU Revenue (margin×clients) | B7: =B6*Assumptions!C30 | C7: =C6*Assumptions!C30 | D7: =D6*Assumptions!C30 | E7: =E6*Assumptions!C30 | F7: =F6*Assumptions!C30 | G7: =G6*Assumptions!C30 | H7: =H6*Assumptions!C30 | I7: =I6*Assumptions!C30 | J7: =J6*Assumptions!C30 | K7: =K6*Assumptions!C30 | L7: =L6*Assumptions!C30 | M7: =M6*Assumptions!C30
A8: Pro Subscription Revenue | B8: ='User Growth'!B23*Assumptions!C24 | C8: ='User Growth'!C23*Assumptions!C24 | D8: ='User Growth'!D23*Assumptions!C24 | E8: ='User Growth'!E23*Assumptions!C24 | F8: ='User Growth'!F23*Assumptions!C24 | G8: ='User Growth'!G23*Assumptions!C24 | H8: ='User Growth'!H23*Assumptions!C24 | I8: ='User Growth'!I23*Assumptions!C24 | J8: ='User Growth'!J23*Assumptions!C24 | K8: ='User Growth'!K23*Assumptions!C24 | L8: ='User Growth'!L23*Assumptions!C24 | M8: ='User Growth'!M23*Assumptions!C24
A9: GROSS REVENUE | B9: =B7+B8 | C9: =C7+C8 | D9: =D7+D8 | E9: =E7+E8 | F9: =F7+F8 | G9: =G7+G8 | H9: =H7+H8 | I9: =I7+I8 | ... M9: =M7+M8
A11: VARIABLE COSTS (4P COGS)
A12: 4p COGS (issuance+deposit) | B12: =B6*Assumptions!C31 | C12: =C6*Assumptions!C31 | D12: =D6*Assumptions!C31 | E12: =E6*Assumptions!C31 | F12: =F6*Assumptions!C31 | G12: =G6*Assumptions!C31 | H12: =H6*Assumptions!C31 | I12: =I6*Assumptions!C31 | J12: =J6*Assumptions!C31 | K12: =K6*Assumptions!C31 | L12: =L6*Assumptions!C31 | M12: =M6*Assumptions!C31
A14: FIXED EXPENSES
A15: Hosting | B15: =Assumptions!C46 | C15: =Assumptions!C46 | D15: =Assumptions!C46 | E15: =Assumptions!C46 | F15: =Assumptions!C46 | G15: =Assumptions!C46 | H15: =Assumptions!C46 | I15: =Assumptions!C46 | J15: =Assumptions!C46 | K15: =Assumptions!C46 | L15: =Assumptions!C46 | M15: =Assumptions!C46
A16: 4p Platform Fee | B16: =Assumptions!C47 | C16: =Assumptions!C47 | D16: =Assumptions!C47 | E16: =Assumptions!C47 | F16: =Assumptions!C47 | G16: =Assumptions!C47 | H16: =Assumptions!C47 | I16: =Assumptions!C47 | J16: =Assumptions!C47 | K16: =Assumptions!C47 | L16: =Assumptions!C47 | M16: =Assumptions!C47
A17: Domain+Tooling | B17: =Assumptions!C48 | C17: =Assumptions!C48 | D17: =Assumptions!C48 | E17: =Assumptions!C48 | F17: =Assumptions!C48 | G17: =Assumptions!C48 | H17: =Assumptions!C48 | I17: =Assumptions!C48 | J17: =Assumptions!C48 | K17: =Assumptions!C48 | L17: =Assumptions!C48 | M17: =Assumptions!C48
A18: Marketing | B18: =Assumptions!C49 | C18: =Assumptions!C49 | D18: =Assumptions!C49 | E18: =Assumptions!C49 | F18: =Assumptions!C49 | G18: =Assumptions!C49 | H18: =Assumptions!C49 | I18: =Assumptions!C49 | J18: =Assumptions!C49 | K18: =Assumptions!C49 | L18: =Assumptions!C49 | M18: =Assumptions!C49
A19: CTO/Dev | B19: =Assumptions!C50 | C19: =Assumptions!C50 | D19: =Assumptions!C50 | E19: =Assumptions!C50 | F19: =Assumptions!C50 | G19: =Assumptions!C50 | H19: =Assumptions!C50 | I19: =Assumptions!C50 | J19: =Assumptions!C50 | K19: =Assumptions!C50 | L19: =Assumptions!C50 | M19: =Assumptions!C50
A20: Legal | B20: =Assumptions!C51 | C20: =Assumptions!C51 | D20: =Assumptions!C51 | E20: =Assumptions!C51 | F20: =Assumptions!C51 | G20: =Assumptions!C51 | H20: =Assumptions!C51 | I20: =Assumptions!C51 | J20: =Assumptions!C51 | K20: =Assumptions!C51 | L20: =Assumptions!C51 | M20: =Assumptions!C51
A21: XLM Rewards | B21: ='XLM Rewards'!B19 | C21: ='XLM Rewards'!C19 | D21: ='XLM Rewards'!D19 | E21: ='XLM Rewards'!E19 | F21: ='XLM Rewards'!F19 | G21: ='XLM Rewards'!G19 | H21: ='XLM Rewards'!H19 | I21: ='XLM Rewards'!I19 | ... M21: ='XLM Rewards'!M19
A22: TOTAL EXPENSES | B22: =B3+B12+SUM(B15:B21) | C22: =C3+C12+SUM(C15:C21) | D22: =D3+D12+SUM(D15:D21) | E22: =E3+E12+SUM(E15:E21) | F22: =F3+F12+SUM(F15:F21) | G22: =G3+G12+SUM(G15:G21) | H22: =H3+H12+SUM(H15:H21) | I22: =I3+I12+SUM(I15:I21) | ... M22: =M3+M12+SUM(M15:M21)
A24: NET RESULT
A25: Monthly P/L | B25: =B9-B22 | C25: =C9-C22 | D25: =D9-D22 | E25: =E9-E22 | F25: =F9-F22 | G25: =G9-G22 | H25: =H9-H22 | I25: =I9-I22 | ... M25: =M9-M22
A26: Cumulative P/L | B26: =B25 | C26: =B26+C25 | D26: =C26+D25 | E26: =D26+E25 | F26: =E26+F25 | G26: =F26+G25 | H26: =G26+H25 | I26: =H26+I25 | J26: =I26+J25 | ... M26: =L26+M25
A28: BREAK-EVEN
A29: Fixed Costs/mo | B29: =Assumptions!C53
A30: Net Margin/client | B30: =Assumptions!C32
A31: Break-Even Clients | B31: =CEILING(B29/B30,1) | C31: ← monthly cash-flow +
A33: Max Cash Burn | B33: =MIN(B26:M26)

Sheet XLM Rewards
A1: XLM REWARDS & FREE CARDS
A2: FREE = waived fees. User pays load via USDC. We cover $3.30 per card from grant.
A4: PARAMETERS
A5: Parameter | B5: Value | M5: Notes
A6: Free Cards Budget (count) | B6: 500 | M6: First 500 users
A7: Our Cost per Free Card ($) | B7: 3.3 | M7: $3 issuance + 3%×$10 deposit (FEES ONLY)
A8: XLM Signup Bonus (XLM) | B8: 10 | M8: ≈$1 at current price
A9: XLM Spend Reward (%) | B9: 5 | M9: 5% cashback in XLM
A10: Avg Monthly Spend ($) | B10: 30 | M10: Agent card spend
A11: XLM Price (USD) | B11: 0.1 | M11: Current market
A12: Grant Budget for Rewards ($) | B12: 5000 | M12: Portion of SCF grant
A14: MONTHLY COSTS
B15: Mo 1 | C15: Mo 2 | D15: Mo 3 | E15: Mo 4 | F15: Mo 5 | G15: Mo 6 | H15: Mo 7 | I15: Mo 8 | J15: Mo 9 | K15: Mo 10 | L15: Mo 11 | M15: Mo 12
A16: Free Cards Issued | B16: =MIN('User Growth'!B3,B6) | C16: =MIN('User Growth'!C3,MAX(B6-SUM(B16:B16),0)) | D16: =MIN('User Growth'!D3,MAX(B6-SUM(B16:C16),0)) | E16: =MIN('User Growth'!E3,MAX(B6-SUM(B16:D16),0)) | F16: =MIN('User Growth'!F3,MAX(B6-SUM(B16:E16),0)) | G16: =MIN('User Growth'!G3,MAX(B6-SUM(B16:F16),0)) | H16: =MIN('User Growth'!H3,MAX(B6-SUM(B16:G16),0)) | I16: =MIN('User Growth'!I3,MAX(B6-SUM(B16:H16),0)) | J16: =MIN('User Growth'!J3,MAX(B6-SUM(B16:I16),0)) | K16: =MIN('User Growth'!K3,MAX(B6-SUM(B16:J16),0)) | L16: =MIN('User Growth'!L3,MAX(B6-SUM(B16:K16),0)) | M16: =MIN('User Growth'!M3,MAX(B6-SUM(B16:L16),0))
A17: Free Card Cost ($) | B17: =B16*B7 | C17: =C16*B7 | D17: =D16*B7 | E17: =E16*B7 | F17: =F16*B7 | G17: =G16*B7 | H17: =H16*B7 | I17: =I16*B7 | J17: =J16*B7 | K17: =K16*B7 | L17: =L16*B7 | M17: =M16*B7
A18: Signup Bonuses ($) | B18: =B16*B8*B11 | C18: =C16*B8*B11 | D18: =D16*B8*B11 | E18: =E16*B8*B11 | F18: =F16*B8*B11 | G18: =G16*B8*B11 | H18: =H16*B8*B11 | I18: =I16*B8*B11 | J18: =J16*B8*B11 | K18: =K16*B8*B11 | L18: =L16*B8*B11 | M18: =M16*B8*B11
A19: Spend Cashback ($) | B19: ='User Growth'!B6*B10*(B9/100)*B11 | C19: ='User Growth'!C6*B10*(B9/100)*B11 | D19: ='User Growth'!D6*B10*(B9/100)*B11 | E19: ='User Growth'!E6*B10*(B9/100)*B11 | F19: ='User Growth'!F6*B10*(B9/100)*B11 | G19: ='User Growth'!G6*B10*(B9/100)*B11 | H19: ='User Growth'!H6*B10*(B9/100)*B11 | I19: ='User Growth'!I6*B10*(B9/100)*B11 | J19: ='User Growth'!J6*B10*(B9/100)*B11 | K19: ='User Growth'!K6*B10*(B9/100)*B11 | L19: ='User Growth'!L6*B10*(B9/100)*B11 | M19: ='User Growth'!M6*B10*(B9/100)*B11
A20: TOTAL REWARD COST | B20: =B17+B18+B19 | C20: =C17+C18+C19 | D20: =D17+D18+D19 | E20: =E17+E18+E19 | F20: =F17+F18+F19 | G20: =G17+G18+G19 | H20: =H17+H18+H19 | I20: =I17+I18+I19 | ... M20: =M17+M18+M19
A22: BUDGET TRACKING
A23: Cumulative Spend | B23: =B20 | C23: =B23+C20 | D23: =C23+D20 | E23: =D23+E20 | F23: =E23+F20 | G23: =F23+G20 | H23: =G23+H20 | I23: =H23+I20 | J23: =I23+J20 | ... M23: =L23+M20
A24: Grant Budget Remaining | B24: =B12-B23 | C24: =B12-C23 | D24: =B12-D23 | E24: =B12-E23 | F24: =B12-F23 | G24: =B12-G23 | H24: =B12-H23 | I24: =B12-I23 | J24: =B12-J23 | K24: =B12-K23 | L24: =B12-L23 | M24: =B12-M23
A26: XLM REWARDS STRATEGY
A27: 1. Free Card Issuance | B27: First 500 users get free $10 card — waived fees ($3.30 from grant). Zero friction.
A28: 2. XLM Signup Bonus | B28: 10 XLM airdrop on first card — teaches agents to hold XLM in Stellar wallet.
A29: 3. Spend Cashback in XLM | B29: 5% of card spend returned as XLM — drives recurring usage + grows Stellar TVL.
A30: 4. Stellar Wallet Onboarding | B30: SDK auto-creates Stellar wallet for each agent — instant ecosystem growth.
A31: 5. XLM → Repeat Purchase | B31: Agent earns XLM → uses XLM for next card → self-sustaining flywheel.
A32: 6. Referral in XLM | B32: 20 XLM per referred user who creates first card — viral loop.
A33: 7. SCF Grant Alignment | B33: All costs funded by SCF grant — proves Stellar ecosystem growth to SDF.
A35: SCF GRANT ROI (for reviewers)
A36: → Every free card = new Stellar wallet + USDC settlement on-chain
A37: → XLM rewards create active wallet holders — direct SDF ecosystem metric
A38: → Measurable: cards issued, wallets created, USDC volume, XLM distributed
A39: → Grant ROI: $5,000 → 500 wallets + $15K+ USDC settled on Stellar
A40: → Post-grant self-sustaining: paid users fund ongoing rewards

Sheet Sensitivity
A1: SENSITIVITY ANALYSIS
A3: BREAK-EVEN = Fixed Costs ÷ Net Margin/Client
A4: Cost \ Margin | B4: $4/mo | C4: $6/mo | D4: $8/mo | E4: $10/mo | F4: $12/mo | G4: $15/mo | H4: $20/mo
A5: $200/mo | B5: 50 | C5: 33 | D5: 25 | E5: 20 | F5: 17 | G5: 13 | H5: 10
A6: $400/mo | B6: 100 | C6: 67 | D6: 50 | E6: 40 | F6: 33 | G6: 27 | H6: 20
A7: $600/mo | B7: 150 | C7: 100 | D7: 75 | E7: 60 | F7: 50 | G7: 40 | H7: 30
A8: $800/mo | B8: 200 | C8: 133 | D8: 100 | E8: 80 | F8: 67 | G8: 53 | H8: 40
A9: $1000/mo | B9: 250 | C9: 167 | D9: 125 | E9: 100 | F9: 83 | G9: 67 | H9: 50
A10: $1500/mo | B10: 375 | C10: 250 | D10: 188 | E10: 150 | F10: 125 | G10: 100 | H10: 75
A11: $2000/mo | B11: 500 | C11: 333 | D11: 250 | E11: 200 | F11: 167 | G11: 133 | H11: 100
A12: $3000/mo | B12: 750 | C12: 500 | D12: 375 | E12: 300 | F12: 250 | G12: 200 | H12: 150

Sheet KPI Dashboard
A1: WEEKLY KPI TRACKER
A3: METRICS
A4: Metric | B4: ✅ Target | C4: ⚠️ Warning | D4: 🚩 Critical | E4: Wk1 | F4: Wk2 | G4: Wk3 | H4: Wk4
A5: New Signups/wk | B5: >10 | C5: 3–10 | D5: <3
A6: Free→Paid % | B6: >20% | C6: 10–20% | D6: <10%
A7: Txns/wk | B7: >30 | C7: 10–30 | D7: <10
A8: Weekly Rev | B8: >$200 | C8: $50–200 | D8: <$50
A9: Churn | B9: <5% | C9: 5–10% | D9: >10%
A10: Uptime | B10: >99.5% | C10: 97–99.5% | D10: <97%
A11: Pro Subs/wk | B11: >5 | C11: 1–5 | D11: 0
A12: MRR | B12: >$500 | C12: $100–500 | D12: <$100
A13: XLM Wallets/wk | B13: >20 | C13: 5–20 | D13: <5
A14: Free Cards/wk | B14: >15 | C14: 5–15 | D14: <5
